1. При поврторном добавлении удаленного сигнала:
            Traceback (most recent call last):
            File "h:/My_Works/Python/02_TG_naladka/main.py", line 50, in <lambda>
                btn_base_axe_add.clicked.connect(lambda: self.add_signal(self.qlist_base_axe, self.dict_base_axe))
            File "h:/My_Works/Python/02_TG_naladka/main.py", line 242, in add_signal
                remove_row = self.dict_all_signals.pop(add_signal)
            KeyError: 'фрЄр/тЁхь 
2. Нельзя добавить сигнал в QTable (Ось X):
            Traceback (most recent call last):
            File "h:/My_Works/Python/02_TG_naladka/main.py", line 80, in <lambda>
                btn_x_axe_add.clicked.connect(lambda: self.add_signal(self.qlist_x_axe, self.dict_x_axe))
            File "h:/My_Works/Python/02_TG_naladka/main.py", line 242, in add_signal
                remove_row = self.dict_all_signals.pop(add_signal)
            KeyError: 'фрЄр/тЁхь '
3. При добавлении сигнала в QTable (вспомогательная ОСь):
            Traceback (most recent call last):
            File "d:\My_work\Python\02_TG_naladka\main.py", line 322, in plot_grath
                self.grath = WindowGrath(self.df, self.base_signals, self.secondary_signals, *self.x_axe, 
                            ^^^^^^^^^^^^^^^^^^^^^^^^^^^^^^^^^^^^^^^^^^^^^^^^^^^^^^^^^^^^^^^^^^^^^^^^^^^^
            File "d:\My_work\Python\02_TG_naladka\grath_matplot.py", line 42, in __init__
                self.ui()
            File "d:\My_work\Python\02_TG_naladka\grath_matplot.py", line 87, in ui
                self.plot()
            File "d:\My_work\Python\02_TG_naladka\grath_matplot.py", line 123, in plot
                ax2 = ax1.twinx()  # instantiate a second axes that shares the same x-axis
                    ^^^
            UnboundLocalError: cannot access local variable 'ax1' where it is not associated with a value
            (base) 