1. При поврторном добавлении удаленного сигнала:
            Traceback (most recent call last):
            File "h:/My_Works/Python/02_TG_naladka/main.py", line 50, in <lambda>
                btn_base_axe_add.clicked.connect(lambda: self.add_signal(self.qlist_base_axe, self.dict_base_axe))
            File "h:/My_Works/Python/02_TG_naladka/main.py", line 242, in add_signal
                remove_row = self.dict_all_signals.pop(add_signal)
            KeyError: 'фрЄр/тЁхь 